<?xml version="1.0" ?>
<!-- =================================================================================== -->
<!-- |    This document was autogenerated by xacro from robot.xacro                    | -->
<!-- |    EDITING THIS FILE BY HAND IS NOT RECOMMENDED                                 | -->
<!-- =================================================================================== -->
<robot name="robot">
  <!-- Materials -->
  <material name="white">
    <color rgba="1 1 1 1"/>
  </material>
  <material name="orange">
    <color rgba="0.3 0 0.3 1"/>
  </material>
  <material name="blue">
    <color rgba="0.2 0.2 1 1"/>
  </material>
  <material name="black">
    <color rgba="0 0 0 1"/>
  </material>
  <material name="red">
    <color rgba="1 0 0 1"/>
  </material>
  <!-- Base Link -->
  <link name="base_link"/>
  <link name="base_footprint"/>
  <joint name="base_footprint_joint" type="fixed">
    <parent link="base_link"/>
    <child link="base_footprint"/>
    <origin rpy="0 0 0" xyz="0 0 -0.138"/>
  </joint>
  <!-- Chassis -->
  <joint name="chassis_joint" type="fixed">
    <parent link="base_link"/>
    <child link="chassis"/>
    <origin xyz="-0.4 0 -0.05"/>
  </joint>
  <link name="chassis">
    <inertial>
      <origin rpy="0 0 0" xyz="0.25 0 0.1"/>
      <mass value="1.0"/>
      <inertia ixx="0.08666666666666667" ixy="0.0" ixz="0.0" iyy="0.02416666666666667" iyz="0.0" izz="0.10416666666666666"/>
    </inertial>
    <visual>
      <origin xyz="0.25 0 0.1"/>
      <geometry>
        <box size="0.5 1 0.2"/>
      </geometry>
      <material name="orange"/>
    </visual>
    <collision>
      <origin xyz="0.25 0 0.1"/>
      <geometry>
        <box size="0.5 1 0.2"/>
      </geometry>
    </collision>
  </link>
  <gazebo reference="chassis">
    <material>Gazebo/Orange</material>
  </gazebo>
  <!-- Left Wheel -->
  <joint name="left_wheel_joint" type="continuous">
    <parent link="base_link"/>
    <child link="left_wheel"/>
    <origin rpy="-1.5707963267948966 0 3.141592653589793" xyz="0 0.5 0"/>
    <axis xyz="0 0 1"/>
  </joint>
  <link name="left_wheel">
    <visual>
      <geometry>
        <cylinder length="0.026" radius="0.1"/>
      </geometry>
      <material name="blue"/>
    </visual>
    <collision>
      <geometry>
        <cylinder length="0.026" radius="0.1"/>
      </geometry>
    </collision>
    <inertial>
      <origin rpy="0 0 0" xyz="0 0 0"/>
      <mass value="0.05"/>
      <inertia ixx="0.0001278166666666667" ixy="0.0" ixz="0.0" iyy="0.0001278166666666667" iyz="0.0" izz="0.00025000000000000006"/>
    </inertial>
  </link>
  <gazebo reference="left_wheel">
    <material>Gazebo/Blue</material>
  </gazebo>
  <!-- Right Wheel (Restored) -->
  <joint name="right_wheel_joint" type="continuous">
    <parent link="base_link"/>
    <child link="right_wheel"/>
    <origin rpy="1.5707963267948966 0 3.141592653589793" xyz="0 -0.5 0"/>
    <axis xyz="0 0 -1"/>
  </joint>
  <link name="right_wheel">
    <visual>
      <geometry>
        <cylinder length="0.026" radius="0.1"/>
      </geometry>
      <material name="blue"/>
    </visual>
    <collision>
      <geometry>
        <cylinder length="0.026" radius="0.1"/>
      </geometry>
    </collision>
    <inertial>
      <origin rpy="0 0 0" xyz="0 0 0"/>
      <mass value="0.05"/>
      <inertia ixx="0.0001278166666666667" ixy="0.0" ixz="0.0" iyy="0.0001278166666666667" iyz="0.0" izz="0.00025000000000000006"/>
    </inertial>
  </link>
  <gazebo reference="right_wheel">
    <material>Gazebo/Blue</material>
  </gazebo>
  <!-- Caster Wheel -->
  <joint name="caster_wheel_joint" type="fixed">
    <parent link="chassis"/>
    <child link="caster_wheel"/>
    <origin xyz="0.075 0 0.0"/>
  </joint>
  <link name="caster_wheel">
    <visual>
      <geometry>
        <sphere radius="0.05"/>
      </geometry>
      <material name="black"/>
    </visual>
    <collision>
      <geometry>
        <sphere radius="0.05"/>
      </geometry>
    </collision>
    <inertial>
      <origin rpy="0 0 0" xyz="0 0 0"/>
      <mass value="0.01"/>
      <inertia ixx="1.0000000000000003e-05" ixy="0.0" ixz="0.0" iyy="1.0000000000000003e-05" iyz="0.0" izz="1.0000000000000003e-05"/>
    </inertial>
  </link>
  <gazebo reference="caster_wheel">
    <material>Gazebo/Black</material>
    <mu1 value="0.001"/>
    <mu2 value="0.001"/>
  </gazebo>
  <!-- Tail -->
  <joint name="tail" type="fixed">
    <parent link="chassis"/>
    <child link="tail_link"/>
    <origin rpy="0.0 0.0 0" xyz="0.5 0 0.22"/>
  </joint>
  <link name="tail_link">
    <visual>
      <geometry>
        <box size="0.25 0.05 0.05"/>
      </geometry>
      <material name="white"/>
    </visual>
    <collision>
      <geometry>
        <box size="0.25 0.05 0.05"/>
      </geometry>
    </collision>
    <inertial>
      <origin rpy="0 0 0" xyz="0.5 0 0.22"/>
      <mass value="0.001"/>
      <inertia ixx="4.166666666666667e-07" ixy="0.0" ixz="0.0" iyy="6.770833333333333e-05" iyz="0.0" izz="6.770833333333333e-05"/>
    </inertial>
  </link>
  <gazebo reference="tail_link">
    <material>Gazebo/White</material>
    <mu1 value="0.001"/>
    <mu2 value="0.001"/>
  </gazebo>
  <!-- Plugins -->
  <gazebo>
    <plugin filename="gz-sim-joint-state-publisher-system" name="gz::sim::systems::JointStatePublisher"/>
    <plugin filename="gz-sim-diff-drive-system" name="gz::sim::systems::DiffDrive">
      <left_joint>left_wheel_joint</left_joint>
      <right_joint>right_wheel_joint</right_joint>
      <child_frame_id>robot/base_link</child_frame_id>
      <wheel_separation>0.291</wheel_separation>
      <wheel_radius>0.1</wheel_radius>
      <odom_publish_frequency>10</odom_publish_frequency>
    </plugin>
  </gazebo>
</robot>
